Traceback (most recent call last):
  File "/Users/mike/plate-order-system/venv/lib/python3.10/site-packages/pydantic_settings/sources.py", line 610, in __call__
    field_value = self.prepare_field_value(field_name, field, field_value, value_is_complex)
  File "/Users/mike/plate-order-system/venv/lib/python3.10/site-packages/pydantic_settings/sources.py", line 827, in prepare_field_value
    raise e
  File "/Users/mike/plate-order-system/venv/lib/python3.10/site-packages/pydantic_settings/sources.py", line 824, in prepare_field_value
    value = self.decode_complex_value(field_name, field, value)
  File "/Users/mike/plate-order-system/venv/lib/python3.10/site-packages/pydantic_settings/sources.py", line 333, in decode_complex_value
    return json.loads(value)
  File "/Users/mike/.pyenv/versions/3.10.12/lib/python3.10/json/__init__.py", line 346, in loads
    return _default_decoder.decode(s)
  File "/Users/mike/.pyenv/versions/3.10.12/lib/python3.10/json/decoder.py", line 337, in decode
    obj, end = self.raw_decode(s, idx=_w(s, 0).end())
  File "/Users/mike/.pyenv/versions/3.10.12/lib/python3.10/json/decoder.py", line 355, in raw_decode
    raise JSONDecodeError("Expecting value", s, err.value) from None
json.decoder.JSONDecodeError: Expecting value: line 1 column 1 (char 0)

The above exception was the direct cause of the following exception:

Traceback (most recent call last):
  File "/Users/mike/plate-order-system/backend/main.py", line 10, in <module>
    from app.core.config import settings
  File "/Users/mike/plate-order-system/backend/app/core/config.py", line 73, in <module>
    settings = Settings()
  File "/Users/mike/plate-order-system/venv/lib/python3.10/site-packages/pydantic_settings/main.py", line 177, in __init__
    **__pydantic_self__._settings_build_values(
  File "/Users/mike/plate-order-system/venv/lib/python3.10/site-packages/pydantic_settings/main.py", line 408, in _settings_build_values
    source_state = source()
  File "/Users/mike/plate-order-system/venv/lib/python3.10/site-packages/pydantic_settings/sources.py", line 612, in __call__
    raise SettingsError(
pydantic_settings.sources.SettingsError: error parsing value for field "CORS_ORIGINS" from source "EnvSettingsSource"
